{"uuid": "0e0fa9e3-58ed-4350-8a50-ee127a774b3d", "children": ["f6f2e157-1f5b-4818-8ae6-1858b763c970", "1f1eee1f-d5f4-4c02-8460-7ed439818a68", "7850b2aa-5d77-4404-a09e-edf67b298757", "9f70c7b7-391c-4b62-8e98-db8f1310a3b6"], "befores": [{"name": "driver", "status": "broken", "statusDetails": {"message": "selenium.common.exceptions.WebDriverException: Message: An unknown server-side error occurred while processing the command. Original error: Either provide 'app' option to install 'com.ajaxsystems' or consider setting 'noReset' to 'true' if 'com.ajaxsystems' is supposed to be preinstalled.\nStacktrace:\nUnknownError: An unknown server-side error occurred while processing the command. Original error: Either provide 'app' option to install 'com.ajaxsystems' or consider setting 'noReset' to 'true' if 'com.ajaxsystems' is supposed to be preinstalled.\n    at getResponseForW3CError (/opt/homebrew/lib/node_modules/appium/node_modules/@appium/base-driver/lib/protocol/errors.js:1145:9)\n    at asyncHandler (/opt/homebrew/lib/node_modules/appium/node_modules/@appium/base-driver/lib/protocol/protocol.js:485:57)\n", "trace": "  File \"/Users/ilonapetenko/Documents/test_task-main/venv/lib/python3.12/site-packages/pluggy/_callers.py\", line 77, in _multicall\n    res = hook_impl.function(*args)\n          ^^^^^^^^^^^^^^^^^^^^^^^^^\n  File \"/Users/ilonapetenko/Documents/test_task-main/venv/lib/python3.12/site-packages/_pytest/fixtures.py\", line 1123, in pytest_fixture_setup\n    result = call_fixture_func(fixturefunc, request, kwargs)\n             ^^^^^^^^^^^^^^^^^^^^^^^^^^^^^^^^^^^^^^^^^^^^^^^\n  File \"/Users/ilonapetenko/Documents/test_task-main/venv/lib/python3.12/site-packages/_pytest/fixtures.py\", line 895, in call_fixture_func\n    fixture_result = next(generator)\n                     ^^^^^^^^^^^^^^^\n  File \"/Users/ilonapetenko/Documents/test_task-main/tests/conftest.py\", line 38, in driver\n    driver = webdriver.Remote('http://localhost:4723', options=options)\n             ^^^^^^^^^^^^^^^^^^^^^^^^^^^^^^^^^^^^^^^^^^^^^^^^^^^^^^^^^^\n  File \"/Users/ilonapetenko/Documents/test_task-main/venv/lib/python3.12/site-packages/appium/webdriver/webdriver.py\", line 229, in __init__\n    super().__init__(\n  File \"/Users/ilonapetenko/Documents/test_task-main/venv/lib/python3.12/site-packages/selenium/webdriver/remote/webdriver.py\", line 205, in __init__\n    self.start_session(capabilities)\n  File \"/Users/ilonapetenko/Documents/test_task-main/venv/lib/python3.12/site-packages/appium/webdriver/webdriver.py\", line 318, in start_session\n    response = self.execute(RemoteCommand.NEW_SESSION, w3c_caps)\n               ^^^^^^^^^^^^^^^^^^^^^^^^^^^^^^^^^^^^^^^^^^^^^^^^^\n  File \"/Users/ilonapetenko/Documents/test_task-main/venv/lib/python3.12/site-packages/selenium/webdriver/remote/webdriver.py\", line 344, in execute\n    self.error_handler.check_response(response)\n  File \"/Users/ilonapetenko/Documents/test_task-main/venv/lib/python3.12/site-packages/selenium/webdriver/remote/errorhandler.py\", line 229, in check_response\n    raise exception_class(message, screen, stacktrace)\n"}, "start": 1730748737016, "stop": 1730748737817}], "start": 1730748737016, "stop": 1730748737893}