{"uuid": "d754d427-ff83-48b9-a891-41a1d7c192ec", "children": ["23e4f4e4-a0bf-4a96-9b12-f041d9170d7e", "30cf84ba-ee3d-4c79-9068-d98a5ee10b43", "cd647766-be0d-4ea3-a85a-2aa34809ab3b", "3296f1fd-ad29-4a05-a432-effa32413e94"], "befores": [{"name": "driver", "status": "broken", "statusDetails": {"message": "selenium.common.exceptions.SessionNotCreatedException: Message: A new session could not be created. Details: 'udid' must be of type string\nStacktrace:\nSessionNotCreatedError: A new session could not be created. Details: 'udid' must be of type string\n    at AndroidUiautomator2Driver.createSession (/opt/homebrew/lib/node_modules/appium/node_modules/@appium/base-driver/lib/basedriver/driver.ts:298:13)\n    at AndroidUiautomator2Driver.createSession (/Users/ilonapetenko/.appium/node_modules/appium-uiautomator2-driver/lib/driver.ts:334:75)\n    at AppiumDriver.createSession (/opt/homebrew/lib/node_modules/appium/lib/appium.js:739:56)\n", "trace": "  File \"/Users/ilonapetenko/Documents/test_task-main/venv/lib/python3.12/site-packages/pluggy/_callers.py\", line 77, in _multicall\n    res = hook_impl.function(*args)\n          ^^^^^^^^^^^^^^^^^^^^^^^^^\n  File \"/Users/ilonapetenko/Documents/test_task-main/venv/lib/python3.12/site-packages/_pytest/fixtures.py\", line 1123, in pytest_fixture_setup\n    result = call_fixture_func(fixturefunc, request, kwargs)\n             ^^^^^^^^^^^^^^^^^^^^^^^^^^^^^^^^^^^^^^^^^^^^^^^\n  File \"/Users/ilonapetenko/Documents/test_task-main/venv/lib/python3.12/site-packages/_pytest/fixtures.py\", line 895, in call_fixture_func\n    fixture_result = next(generator)\n                     ^^^^^^^^^^^^^^^\n  File \"/Users/ilonapetenko/Documents/test_task-main/tests/conftest.py\", line 38, in driver\n    driver = webdriver.Remote('http://localhost:4723', options=options)\n             ^^^^^^^^^^^^^^^^^^^^^^^^^^^^^^^^^^^^^^^^^^^^^^^^^^^^^^^^^^\n  File \"/Users/ilonapetenko/Documents/test_task-main/venv/lib/python3.12/site-packages/appium/webdriver/webdriver.py\", line 229, in __init__\n    super().__init__(\n  File \"/Users/ilonapetenko/Documents/test_task-main/venv/lib/python3.12/site-packages/selenium/webdriver/remote/webdriver.py\", line 205, in __init__\n    self.start_session(capabilities)\n  File \"/Users/ilonapetenko/Documents/test_task-main/venv/lib/python3.12/site-packages/appium/webdriver/webdriver.py\", line 318, in start_session\n    response = self.execute(RemoteCommand.NEW_SESSION, w3c_caps)\n               ^^^^^^^^^^^^^^^^^^^^^^^^^^^^^^^^^^^^^^^^^^^^^^^^^\n  File \"/Users/ilonapetenko/Documents/test_task-main/venv/lib/python3.12/site-packages/selenium/webdriver/remote/webdriver.py\", line 344, in execute\n    self.error_handler.check_response(response)\n  File \"/Users/ilonapetenko/Documents/test_task-main/venv/lib/python3.12/site-packages/selenium/webdriver/remote/errorhandler.py\", line 229, in check_response\n    raise exception_class(message, screen, stacktrace)\n"}, "start": 1730748225867, "stop": 1730748225913}], "start": 1730748225867, "stop": 1730748225982}