{"uuid": "0684c081-3915-4937-a9e1-10248062a797", "children": ["4d7e1edb-5613-4f39-9717-96ff15aac9cb", "1e8effd8-b88b-4ce3-a48f-405bbd01a43c", "0c5c566f-f552-478f-945f-1564cfa2c37c"], "befores": [{"name": "driver", "status": "broken", "statusDetails": {"message": "selenium.common.exceptions.SessionNotCreatedException: Message: A new session could not be created. Details: 'udid' must be of type string\nStacktrace:\nSessionNotCreatedError: A new session could not be created. Details: 'udid' must be of type string\n    at AndroidUiautomator2Driver.createSession (/opt/homebrew/lib/node_modules/appium/node_modules/@appium/base-driver/lib/basedriver/driver.ts:298:13)\n    at AndroidUiautomator2Driver.createSession (/Users/ilonapetenko/.appium/node_modules/appium-uiautomator2-driver/lib/driver.ts:334:75)\n    at AppiumDriver.createSession (/opt/homebrew/lib/node_modules/appium/lib/appium.js:739:56)\n", "trace": "  File \"/Users/ilonapetenko/Documents/test_task-main/venv/lib/python3.12/site-packages/pluggy/_callers.py\", line 77, in _multicall\n    res = hook_impl.function(*args)\n          ^^^^^^^^^^^^^^^^^^^^^^^^^\n  File \"/Users/ilonapetenko/Documents/test_task-main/venv/lib/python3.12/site-packages/_pytest/fixtures.py\", line 1123, in pytest_fixture_setup\n    result = call_fixture_func(fixturefunc, request, kwargs)\n             ^^^^^^^^^^^^^^^^^^^^^^^^^^^^^^^^^^^^^^^^^^^^^^^\n  File \"/Users/ilonapetenko/Documents/test_task-main/venv/lib/python3.12/site-packages/_pytest/fixtures.py\", line 895, in call_fixture_func\n    fixture_result = next(generator)\n                     ^^^^^^^^^^^^^^^\n  File \"/Users/ilonapetenko/Documents/test_task-main/tests/conftest.py\", line 38, in driver\n    driver = webdriver.Remote('http://localhost:4723', options=options)\n             ^^^^^^^^^^^^^^^^^^^^^^^^^^^^^^^^^^^^^^^^^^^^^^^^^^^^^^^^^^\n  File \"/Users/ilonapetenko/Documents/test_task-main/venv/lib/python3.12/site-packages/appium/webdriver/webdriver.py\", line 229, in __init__\n    super().__init__(\n  File \"/Users/ilonapetenko/Documents/test_task-main/venv/lib/python3.12/site-packages/selenium/webdriver/remote/webdriver.py\", line 205, in __init__\n    self.start_session(capabilities)\n  File \"/Users/ilonapetenko/Documents/test_task-main/venv/lib/python3.12/site-packages/appium/webdriver/webdriver.py\", line 318, in start_session\n    response = self.execute(RemoteCommand.NEW_SESSION, w3c_caps)\n               ^^^^^^^^^^^^^^^^^^^^^^^^^^^^^^^^^^^^^^^^^^^^^^^^^\n  File \"/Users/ilonapetenko/Documents/test_task-main/venv/lib/python3.12/site-packages/selenium/webdriver/remote/webdriver.py\", line 344, in execute\n    self.error_handler.check_response(response)\n  File \"/Users/ilonapetenko/Documents/test_task-main/venv/lib/python3.12/site-packages/selenium/webdriver/remote/errorhandler.py\", line 229, in check_response\n    raise exception_class(message, screen, stacktrace)\n"}, "start": 1730748142497, "stop": 1730748142523}], "start": 1730748142497, "stop": 1730748142559}